2025-09-04 17:55:31,785 - root - INFO - Create log file at experimental_results/Cora/1757022931.785509.log
2025-09-04 17:55:31,786 - root - INFO - Command line executed: python nc_gc/nc_gc_darts/main.py --dataset Cora --task node --seed 0 --log_dir experimental_results/
2025-09-04 17:55:31,786 - root - INFO - Full args parsed:
2025-09-04 17:55:31,786 - root - INFO - Namespace(train_ratio=0.6, val_ratio=0.2, test_ratio=0.2, model='Auto-GNN', metric='acc', gpu=0, directed=False, parallel=False, optimizer='adam', task='node', dataset='Cora', seed=0, clip=0.1, epoch=20, retrain_epoch=100, layers=4, hidden_features=64, bs=128, lr=0.0005, l2=0.0001, dropout=0, log_dir='experimental_results/', summary_file='result_summary.log', debug=False, use_llm_pruning=False, gcp_project_id=None, gcp_location='us-central1', gcp_credentials_path=None)
2025-09-04 17:55:31,796 - asyncio - DEBUG - Using selector: KqueueSelector
2025-09-04 17:55:31,797 - fsspec.http - DEBUG - https://github.com/kimiyoung/planetoid/raw/master/data/ind.cora.x
2025-09-04 17:55:31,852 - fsspec.http - DEBUG - Retrieve file size for https://github.com/kimiyoung/planetoid/raw/master/data/ind.cora.x
2025-09-04 17:55:31,876 - fsspec.http - DEBUG - 
Traceback (most recent call last):
  File "/Users/School/Documents/AutoGEL-main/venv/lib/python3.13/site-packages/aiohttp/connector.py", line 1283, in _wrap_create_connection
    return await self._loop.create_connection(*args, **kwargs, sock=sock)
           ^^^^^^^^^^^^^^^^^^^^^^^^^^^^^^^^^^^^^^^^^^^^^^^^^^^^^^^^^^^^^^
  File "/opt/homebrew/Cellar/python@3.13/3.13.5/Frameworks/Python.framework/Versions/3.13/lib/python3.13/asyncio/base_events.py", line 1193, in create_connection
    transport, protocol = await self._create_connection_transport(
                          ^^^^^^^^^^^^^^^^^^^^^^^^^^^^^^^^^^^^^^^^
    ...<2 lines>...
        ssl_shutdown_timeout=ssl_shutdown_timeout)
        ^^^^^^^^^^^^^^^^^^^^^^^^^^^^^^^^^^^^^^^^^^
  File "/opt/homebrew/Cellar/python@3.13/3.13.5/Frameworks/Python.framework/Versions/3.13/lib/python3.13/asyncio/base_events.py", line 1226, in _create_connection_transport
    await waiter
  File "/opt/homebrew/Cellar/python@3.13/3.13.5/Frameworks/Python.framework/Versions/3.13/lib/python3.13/asyncio/sslproto.py", line 581, in _on_handshake_complete
    raise handshake_exc
  File "/opt/homebrew/Cellar/python@3.13/3.13.5/Frameworks/Python.framework/Versions/3.13/lib/python3.13/asyncio/sslproto.py", line 563, in _do_handshake
    self._sslobj.do_handshake()
    ~~~~~~~~~~~~~~~~~~~~~~~~~^^
  File "/opt/homebrew/Cellar/python@3.13/3.13.5/Frameworks/Python.framework/Versions/3.13/lib/python3.13/ssl.py", line 951, in do_handshake
    self._sslobj.do_handshake()
    ~~~~~~~~~~~~~~~~~~~~~~~~~^^
ssl.SSLCertVerificationError: [SSL: CERTIFICATE_VERIFY_FAILED] certificate verify failed: self-signed certificate in certificate chain (_ssl.c:1028)

The above exception was the direct cause of the following exception:

Traceback (most recent call last):
  File "/Users/School/Documents/AutoGEL-main/venv/lib/python3.13/site-packages/fsspec/implementations/http.py", line 437, in _info
    await _file_info(
    ...<5 lines>...
    )
  File "/Users/School/Documents/AutoGEL-main/venv/lib/python3.13/site-packages/fsspec/implementations/http.py", line 847, in _file_info
    r = await session.head(url, allow_redirects=ar, **kwargs)
        ^^^^^^^^^^^^^^^^^^^^^^^^^^^^^^^^^^^^^^^^^^^^^^^^^^^^^
  File "/Users/School/Documents/AutoGEL-main/venv/lib/python3.13/site-packages/aiohttp/client.py", line 770, in _request
    resp = await handler(req)
           ^^^^^^^^^^^^^^^^^^
  File "/Users/School/Documents/AutoGEL-main/venv/lib/python3.13/site-packages/aiohttp/client.py", line 725, in _connect_and_send_request
    conn = await self._connector.connect(
           ^^^^^^^^^^^^^^^^^^^^^^^^^^^^^^
        req, traces=traces, timeout=real_timeout
        ^^^^^^^^^^^^^^^^^^^^^^^^^^^^^^^^^^^^^^^^
    )
    ^
  File "/Users/School/Documents/AutoGEL-main/venv/lib/python3.13/site-packages/aiohttp/connector.py", line 642, in connect
    proto = await self._create_connection(req, traces, timeout)
            ^^^^^^^^^^^^^^^^^^^^^^^^^^^^^^^^^^^^^^^^^^^^^^^^^^^
  File "/Users/School/Documents/AutoGEL-main/venv/lib/python3.13/site-packages/aiohttp/connector.py", line 1209, in _create_connection
    _, proto = await self._create_direct_connection(req, traces, timeout)
               ^^^^^^^^^^^^^^^^^^^^^^^^^^^^^^^^^^^^^^^^^^^^^^^^^^^^^^^^^^
  File "/Users/School/Documents/AutoGEL-main/venv/lib/python3.13/site-packages/aiohttp/connector.py", line 1581, in _create_direct_connection
    raise last_exc
  File "/Users/School/Documents/AutoGEL-main/venv/lib/python3.13/site-packages/aiohttp/connector.py", line 1550, in _create_direct_connection
    transp, proto = await self._wrap_create_connection(
                    ^^^^^^^^^^^^^^^^^^^^^^^^^^^^^^^^^^^
    ...<7 lines>...
    )
    ^
  File "/Users/School/Documents/AutoGEL-main/venv/lib/python3.13/site-packages/aiohttp/connector.py", line 1285, in _wrap_create_connection
    raise ClientConnectorCertificateError(req.connection_key, exc) from exc
aiohttp.client_exceptions.ClientConnectorCertificateError: Cannot connect to host github.com:443 ssl:True [SSLCertVerificationError: (1, '[SSL: CERTIFICATE_VERIFY_FAILED] certificate verify failed: self-signed certificate in certificate chain (_ssl.c:1028)')]
2025-09-04 17:55:31,885 - fsspec.http - DEBUG - Retrieve file size for https://github.com/kimiyoung/planetoid/raw/master/data/ind.cora.x
